Workbook

Sheet Checklist
C1: SOP-Link in grey | D1: section name | E1: tasks/name | F1: task complete | G1: section complete | H1: date | I1: comments | N1: Extra1 | O1: Extra2 | P1: Extra3 | Q1: Extra4
C3: Glider:
C4: Current Engineer: | G4: HOW TO USE:
C5: Date Started: | G5: Indicate which sections are required (Y or N)
C6: Deployment Lead personel: | G6: Indicate sensor configuration required (Y or N)
C7: ADF Number: | G7: Fill in config for mission using dropdown
G8: Serial Numbers will auto-populate as sheet is completed
G9: If you prefer, overwrite cell with red 0 with the SN of component
O11: y
D12: Outgoing refurb | T12: Add the notes for dry weights and such | U12: Do the following components need upgrade or replacement
C13: =SUMPRODUCT((F32:G40="y")+(F32:G40="n/a")+(F32:G40="na"))/SUMPRODUCT((F32:G40="y")+(F32:G40="n")+(F32:G40="n/a")+(F32:G40="na")) -> 0 | D13: Office | E13: N | G13: Sci Sensors for Mission | I13: SN | K13: Config for Mission | M13: SN | P13: Science Bay Uarts and bits | U13: pump service
C14: =SUMPRODUCT((F43:G53="y")+(F43:G53="n/a")+(F43:G53="na"))/SUMPRODUCT((F43:G53="y")+(F43:G53="n")+(F43:G53="n/a")+(F43:G53="na")) -> 0.375 | D14: Mid Life Upgrade / Major Component replacement i.e fin | E14: N | G14: SB CT pumped | H14: N | I14: =IF((#REF!="user input"),0,#REF!) -> #REF! | K14: G2/G3 | L14: G3 | O14: sensor | P14: uart | Q14: bit | U14: air-bladder
C15: =SUMPRODUCT((F57:G177="y")+(F57:G177="n/a")+(F57:G177="na"))/SUMPRODUCT((F57:G177="y")+(F57:G177="n")+(F57:G177="n/a")+(F57:G177="na")) -> #REF! | D15: Lab | E15: N | G15: SB CT unpumped | H15: N | I15: =IF((#REF!="user input"),0,#REF!) -> #REF! | K15: Thruster | L15: none | M15: =IF((#REF!="user input"),0,#REF!) -> #REF! | O15: =IFERROR(INDEX($G$14:$G$26,_xlfn.AGGREGATE(15,6,ROW($G$14:$G$26)-ROW($G$14)+1/($G$14:$H$26=$O$11),ROWS(O$15:O15))), " ") -> RBR CT | P15: =IFERROR(VLOOKUP(O15,constants!$K$3:$M$15,2,FALSE)," ") -> user input | Q15: =IFERROR(VLOOKUP(O15,constants!$K$3:$M$15,3,FALSE)," ") -> user input | U15: Aft end MCBH or IE55
C16: =SUMPRODUCT((F181:G201="y")+(F181:G201="n/a")+(F181:G201="na"))/SUMPRODUCT((F181:G201="y")+(F181:G201="n")+(F181:G201="n/a")+(F181:G201="na")) -> 0 | D16: Tank | E16: N | G16: RBR CT | H16: Y | I16: =IF((P109="user input"),0,P109) -> 0 | K16: Pump | L16: G3 1000 | M16: =IF((N95="user input"),0,N95) -> 0 | N16: =IF(N58="user input", "input inflections below", "inflections: " & N58) -> input inflections below | O16: =IFERROR(INDEX($G$14:$G$26,_xlfn.AGGREGATE(15,6,ROW($G$14:$G$26)-ROW($G$14)+1/($G$14:$H$26=$O$11),ROWS(O$15:O16))), " ") -> Optode | P16: =IFERROR(VLOOKUP(O16,constants!$K$3:$M$15,2,FALSE)," ") -> user input | Q16: =IFERROR(VLOOKUP(O16,constants!$K$3:$M$15,3,FALSE)," ") -> user input | U16: digifin
C17: =SUMPRODUCT((F206:G245="y")+(F206:G245="n/a")+(F206:G245="na"))/SUMPRODUCT((F206:G245="y")+(F206:G245="n")+(F206:G245="n/a")+(F206:G245="na")) -> 0.055555556 | D17: Final Seal and FCP | E17: N | G17: WL (type) | H17: N | I17: =IF((#REF!="user input"),0,#REF!) -> #REF! | K17: Altimeter | L17: new | M17: =IF((O95="user input"),0,O95) -> 0 | O17: =IFERROR(INDEX($G$14:$G$26,_xlfn.AGGREGATE(15,6,ROW($G$14:$G$26)-ROW($G$14)+1/($G$14:$H$26=$O$11),ROWS(O$15:O17))), " ") -> Satlantic PAR | P17: =IFERROR(VLOOKUP(O17,constants!$K$3:$M$15,2,FALSE)," ") -> user input | Q17: =IFERROR(VLOOKUP(O17,constants!$K$3:$M$15,3,FALSE)," ") -> user input | U17: End Cap
C18: =SUMPRODUCT((F250:G275="y")+(F250:G275="n/a")+(F250:G275="na"))/SUMPRODUCT((F250:G275="y")+(F250:G275="n")+(F250:G275="n/a")+(F250:G275="na")) -> 0.34782609 | D18: Prep for shipment and deployment | E18: N | G18: Microrider | H18: N | I18: =IF((P115="user input"),0,P115) -> 0 | K18: Science Bay | L18: g3s | M18: =IF((N102="user input"),0,N102) -> 0 | O18: =IFERROR(INDEX($G$14:$G$26,_xlfn.AGGREGATE(15,6,ROW($G$14:$G$26)-ROW($G$14)+1/($G$14:$H$26=$O$11),ROWS(O$15:O18))), " ") -> ADCP down | P18: =IFERROR(VLOOKUP(O18,constants!$K$3:$M$15,2,FALSE)," ") -> user input | Q18: =IFERROR(VLOOKUP(O18,constants!$K$3:$M$15,3,FALSE)," ") -> user input | U18: sci bay to MCBH stifener
D19: Incoming Refurb | G19: Optode | H19: Y | I19: =IF((P124="user input"),0,P124) -> 0 | K19: Stack on sci bay | L19: lith-ion | M19: =IF((P102="user input"),0,P102) -> 0 | O19: =IFERROR(INDEX($G$14:$G$26,_xlfn.AGGREGATE(15,6,ROW($G$14:$G$26)-ROW($G$14)+1/($G$14:$H$26=$O$11),ROWS(O$15:O19))), " ") | P19: =IFERROR(VLOOKUP(O19,constants!$K$3:$M$15,2,FALSE)," ") | Q19: =IFERROR(VLOOKUP(O19,constants!$K$3:$M$15,3,FALSE)," ") | U19: see noets next to extras
C20: =SUMPRODUCT((#REF!="y")+(#REF!="n/a")+(#REF!="na"))/SUMPRODUCT((#REF!="y")+(#REF!="n")+(#REF!="n/a")+(#REF!="na")) -> #REF! | D20: Office | E20: N | G20: Biospeherical PAR | H20: N | I20: =IF((#REF!="user input"),0,#REF!) -> #REF! | K20: Batteries | O20: =IFERROR(INDEX($G$14:$G$26,_xlfn.AGGREGATE(15,6,ROW($G$14:$G$26)-ROW($G$14)+1/($G$14:$H$26=$O$11),ROWS(O$15:O20))), " ") | P20: =IFERROR(VLOOKUP(O20,constants!$K$3:$M$15,2,FALSE)," ") | Q20: =IFERROR(VLOOKUP(O20,constants!$K$3:$M$15,3,FALSE)," ") | U20: makecopy and past output for autoexec SNs
C21: =SUMPRODUCT((F284:G290="y")+(F284:G290="n/a")+(F284:G290="na"))/SUMPRODUCT((F284:G290="y")+(F284:G290="n")+(F284:G290="n/a")+(F284:G290="na")) -> 0.16666667 | D21: Inspect External | E21: N | G21: Satlantic PAR | H21: Y | I21: =IF((P129="user input"),0,P129) -> 0 | L21: Aft | M21: =IF((O84="user input"),0,O84) -> 0 | O21: =IFERROR(INDEX($G$14:$G$26,_xlfn.AGGREGATE(15,6,ROW($G$14:$G$26)-ROW($G$14)+1/($G$14:$H$26=$O$11),ROWS(O$15:O21))), " ") | P21: =IFERROR(VLOOKUP(O21,constants!$K$3:$M$15,2,FALSE)," ") | Q21: =IFERROR(VLOOKUP(O21,constants!$K$3:$M$15,3,FALSE)," ") | U21: make copy and paste section for proglets
C22: =SUMPRODUCT((F293:G302="y")+(F293:G302="n/a")+(F293:G302="na"))/SUMPRODUCT((F293:G302="y")+(F293:G302="n")+(F293:G302="n/a")+(F293:G302="na")) -> 0.22222222 | D22: Data | E22: N | G22: ADCP up | H22: N | I22: =IF((#REF!="user input"),0,#REF!) -> #REF! | L22: Fwd | M22: =IF((N84="user input"),0,N84) -> 0 | N22: =IF(O86="user input", "input pitch weight below", "pitch weight: " & O86 & " g") -> input pitch weight below | O22: =IFERROR(INDEX($G$14:$G$26,_xlfn.AGGREGATE(15,6,ROW($G$14:$G$26)-ROW($G$14)+1/($G$14:$H$26=$O$11),ROWS(O$15:O22))), " ") | P22: =IFERROR(VLOOKUP(O22,constants!$K$3:$M$15,2,FALSE)," ") | Q22: =IFERROR(VLOOKUP(O22,constants!$K$3:$M$15,3,FALSE)," ") | U22: need to make a section for simulations (gneric stuff)
C23: =SUMPRODUCT((F306:G319="y")+(F306:G319="n/a")+(F306:G319="na"))/SUMPRODUCT((F306:G319="y")+(F306:G319="n")+(F306:G319="n/a")+(F306:G319="na")) -> 0.083333333 | D23: Inspect Internal (if opening) | E23: N | G23: ADCP down | H23: Y | I23: =IF((P135="user input"),0,P135) -> 0 | L23: Em | M23: =IF((P84="user input"),0,P84) -> 0 | O23: =IFERROR(INDEX($G$14:$G$26,_xlfn.AGGREGATE(15,6,ROW($G$14:$G$26)-ROW($G$14)+1/($G$14:$H$26=$O$11),ROWS(O$15:O23))), " ") | P23: =IFERROR(VLOOKUP(O23,constants!$K$3:$M$15,2,FALSE)," ") | Q23: =IFERROR(VLOOKUP(O23,constants!$K$3:$M$15,3,FALSE)," ")
C24: =SUMPRODUCT((F322:G326="y")+(F322:G326="n/a")+(F322:G326="na"))/SUMPRODUCT((F322:G326="y")+(F322:G326="n")+(F322:G326="n/a")+(F322:G326="na")) -> 0 | D24: Repairs and storage | E24: N | G24: PAM | H24: N | I24: =IF((#REF!="user input"),0,#REF!) -> #REF! | L24: Ext | M24: =IF((Q84="user input"),0,Q84) -> 0 | O24: =IFERROR(INDEX($G$14:$G$26,_xlfn.AGGREGATE(15,6,ROW($G$14:$G$26)-ROW($G$14)+1/($G$14:$H$26=$O$11),ROWS(O$15:O24))), " ") | P24: =IFERROR(VLOOKUP(O24,constants!$K$3:$M$15,2,FALSE)," ") | Q24: =IFERROR(VLOOKUP(O24,constants!$K$3:$M$15,3,FALSE)," ")
G25: Echosounder | H25: N | I25: =IF((#REF!="user input"),0,#REF!) -> #REF! | K25: Ex. Energy Bay | L25: =IF(ISNUMBER(SEARCH("ext",L19)),L14,"") | M25: =IF((#REF!="user input"),0,#REF!) -> #REF! | O25: =IFERROR(INDEX($G$14:$G$26,_xlfn.AGGREGATE(15,6,ROW($G$14:$G$26)-ROW($G$14)+1/($G$14:$H$26=$O$11),ROWS(O$15:O25))), " ") | P25: =IFERROR(VLOOKUP(O25,constants!$K$3:$M$15,2,FALSE)," ") | Q25: =IFERROR(VLOOKUP(O25,constants!$K$3:$M$15,3,FALSE)," ")
D26: Ballast information | G26: Jasco Observer | H26: N | I26: =IF((#REF!="user input"),0,#REF!) -> #REF! | L26: Digifin | M26: =IF((N48="user input"),0,N48) -> - | O26: =IFERROR(INDEX($G$14:$G$26,_xlfn.AGGREGATE(15,6,ROW($G$14:$G$26)-ROW($G$14)+1/($G$14:$H$26=$O$11),ROWS(O$15:O26))), " ") | P26: =IFERROR(VLOOKUP(O26,constants!$K$3:$M$15,2,FALSE)," ") | Q26: =IFERROR(VLOOKUP(O26,constants!$K$3:$M$15,3,FALSE)," ") | T26: Fix these when not being done
D27: Dry Weight: | E27: =N151 -> user input | L27: Aft cap | M27: =IF((O48="user input"),0,O48) -> - | P27: =IFERROR(VLOOKUP(O27,constants!$K$3:$M$15,2,FALSE)," ") | Q27: =IFERROR(VLOOKUP(O27,constants!$K$3:$M$15,3,FALSE)," ")
D28: pitch battery weight: | E28: =N22 -> input pitch weight below | L28: =N151 -> user input | P28: =IFERROR(VLOOKUP(O28,constants!$K$3:$M$15,2,FALSE)," ") | Q28: =IFERROR(VLOOKUP(O28,constants!$K$3:$M$15,3,FALSE)," ")
T29: NEED TO ADD TO LIST
U30: nose cone and recovery system stuff
C31: =D13 -> Office | F31: Task Complete | G31: =IF(E13="y",IF(AND(G32="complete",G35="complete",#REF!="complete"), "Section Complete", "Section Incomplete"),"Section N/A") -> Section N/A | H31: Date | I31: Comments
C32: Deployment Documentation (Deployment Lead) | G32: =IF(COUNTIF(F33:G34,"y")+COUNTIF(F33:G34,"na")+COUNTIF(F33:G34,"n/a")=COUNTA(F33:G34), "Complete", "Incomplete") -> Incomplete
D33: Start Deployment documents and add to expedition folder | F33: n | N33: - | O33: - | P33: - | Q33: -
D34: Have meeting with PI to go over details for mission | F34: n | N34: - | O34: - | P34: - | Q34: -
C35: Paper work collection | G35: =IF(COUNTIF(F36:G38,"y")+COUNTIF(F36:G38,"na")+COUNTIF(F36:G38,"n/a")=COUNTA(F36:G38), "Complete", "Incomplete") -> Incomplete
D36: Create directory with copies of template checklists/SOPs | F36: n | N36: - | O36: - | P36: - | Q36: -
D37: Get all sensor calibration sheets | F37: n | N37: - | O37: - | P37: - | Q37: -
A38: places for confirmation | D38: Start a new trimsheet: see 'unit_1104_trial_ NOC_TRIMSHEET.xlsm' | F38: n | N38: - | O38: - | P38: - | Q38: -
A39: final seal / FCP | C39: Ballast | G39: =IF(COUNTIF(F40:G40,"Y")+COUNTIF(F40:G40,"na")+COUNTIF(F40:G40,"n/a")=COUNTA(F40:G40), "Complete", "Incomplete") -> Incomplete | N39: - | O39: - | P39: - | Q39: -
D40: Request or workout target surface/max depth T & S data (copernicus) | F40: n | N40: - | O40: - | P40: - | Q40: -
C42: =D14 -> Mid Life Upgrade / Major Component replacement i.e fin | F42: Task Complete | G42: =IF(E14="Y",IF(AND(G43="complete",G49="complete",G52="complete"), "Section Complete", "Section Incomplete"),"Section N/A") -> Section N/A | H42: Date | I42: Comments
C43: Aft | G43: =IF(COUNTIF(F44:G48,"Y")+COUNTIF(F44:G48,"na")+COUNTIF(F44:G48,"n/a")=COUNTA(F44:G48), "Complete", "Incomplete") -> Incomplete | N43: Digifin SN- | O43: Aft cap SN-
...

Sheet automation-nation

Sheet Change Log
A1: Version | B1: Contributor | C1: Change Log
A2: 1.1 | B2: SW | C2: Added thruster type to constants, auto fetch battery undervolts and capacity, a couple of other tweaks | E2: TODO
A3: 1.2 | B3: AC | C3: Revised Final Seal section and some formating, added micro rider sections
A4: 1.3 | B4: AC | C4: Added some notes on SATPAR | E4: add extra bits for If parts need replacing, where to find sop and new SNs etc | M4: --> | R4: Do the following components need upgrade or replacement
A5: 1.4 | B5: AC | C5: added na as an option and still shows complete in the task completed cells | R5: pump service
A6: 1.5 | B6: SW | C6: added mi & ma files check, all mi voltages set to 17 as standard | R6: air-bladder
A7: 1.6 | B7: SW | C7: added science bay and ex energy bay SN. Added Adeniyi's compass chart | R7: Aft end MCBH or IE55
A8: 1.7 | B8: AC | C8: fixed post mission stuff and repairs, also added 'na' to list of options | R8: digifin
A9: 1.7 | B9: AV | C9: fixed some formulas and added some data bars. | R9: End Cap
A10: 1.8 | B10: AC | C10: Added battery information for the type of battery you have | R10: sci bay to MCBH stifener
A11: 1.9 | B11: AC | C11: Added information to Add to IMS for different components
A12: 1.10 | B12: AC | C12: Added More SN for SNs that we need to track
A13: 1.11 | B13: AC | C13: Added Jasco Observer portion of file, added line in pump section to confirm alt is working in air, calibration stuff for science bay oon return
A14: 2 | B14: AC | C14: Moved things around a little. Change FCP to reflect what is being fone on this sheet. Some things were doubled up in both places. This now should fix that issue of doing things multiple times. Moved compass checks and calibration to lab section. This will check that there is nothings changed crazy on the compass. might move this back now to think about it, may want to check compass after the ballast with all the changes made
A15: 2.1 | B15: AC | C15: Added important info pulled to top of sheet as to not 'hunt' for it in the sheet.
A16: 2.2 | B16: AC | C16: Based on previous meeding, added sections for second technician checks and made some quick changes based on the recommendations from meeting
A17: 2.3 | B17: AC | C17: Added IMS stuff on incoming

Sheet constants
A2: Battery type | B2: f_coulomb_capacity | C2: undervolts (G2) | D2: undervolts (G3) | K2: All sensors | L2: uart | M2: pwr
A3: 0 | K3: =Checklist!G14 -> SB CT pumped | L3: =Checklist!#REF! -> #REF! | M3: =Checklist!#REF! -> #REF!
A4: 3s | B4: 702 | C4: 10 | D4: 9.7 | K4: =Checklist!G15 -> SB CT unpumped | L4: =Checklist!#REF! -> #REF! | M4: =Checklist!#REF! -> #REF!
A5: 3s ext | B5: 1026 | C5: 10 | D5: 9.7 | K5: =Checklist!G16 -> RBR CT | L5: =Checklist!N109 -> user input | M5: =Checklist!O109 -> user input
A6: 4s | B6: 540 | C6: 12.5 | D6: 12.5 | K6: =Checklist!G17 -> WL (type) | L6: =Checklist!#REF! -> #REF! | M6: =Checklist!#REF! -> #REF!
A7: 4s ext | B7: 783 | C7: 12.5 | D7: 12.5 | K7: =Checklist!G18 -> Microrider | L7: =Checklist!N115 -> user input | M7: =Checklist!O115 -> user input
A8: lith-ion | B8: 211.1 | C8: 13.5 | D8: 13.5 | K8: =Checklist!G19 -> Optode | L8: =Checklist!N124 -> user input | M8: =Checklist!O124 -> user input
A9: lith-ion ext | B9: 293.8 | C9: 13.5 | D9: 13.5 | K9: =Checklist!G20 -> Biospeherical PAR | L9: =Checklist!#REF! -> #REF! | M9: =Checklist!#REF! -> #REF!
K10: =Checklist!G21 -> Satlantic PAR | L10: =Checklist!N129 -> user input | M10: =Checklist!O129 -> user input
A11: Pump type | B11: f_max_working_depth | C11: f_crush_depth | D11: m_vacuum | K11: =Checklist!G22 -> ADCP up | L11: =Checklist!#REF! -> #REF! | M11: =Checklist!#REF! -> #REF!
A12: 0 | K12: =Checklist!G23 -> ADCP down | L12: =Checklist!N135 -> user input | M12: =Checklist!O135 -> user input
A13: G3 1000 | B13: 1050 | C13: 1200 | D13: 7 | K13: =Checklist!G24 -> PAM | L13: =Checklist!#REF! -> #REF! | M13: =Checklist!#REF! -> #REF!
A14: G2 1000 | B14: 1050 | C14: 1200 | D14: 7 | K14: =Checklist!G25 -> Echosounder | L14: =Checklist!#REF! -> #REF! | M14: =Checklist!#REF! -> #REF!
A15: G3 350 | B15: 360 | C15: 380 | D15: 7 | K15: =Checklist!G26 -> Jasco Observer | L15: =Checklist!#REF! -> #REF! | M15: =Checklist!#REF! -> #REF!
A16: G3 200 | B16: 206 | C16: 250 | D16: 6
A17: G2 200 | B17: 206 | C17: 250 | D17: 6
A19: Thruster type | C19: Altimeter type
A20: none | C20: old
A21: 6W | C21: new
A22: 10W
A24: Glider type | C24: Sci Bay type
A25: G2 | C25: gen1
A26: G3 | C26: gen2
C27: g3s
A28: Y | B28: confirmed
A29: N | B29: NOT confirmed
A30: N/A | B30: unsure
A31: na
A32: Compass check & cal
A33: desired | C33: Pre-cal compass check | F33: Post-cal compass check
C34: actual | D34: error | F34: actual | G34: error
A35: 0 | C35: =IF(Checklist!I157>0,Checklist!I157, FALSE) -> FALSE | D35: =IF(C35<180, C35-A35, C35-360) -> -360 | F35: =IF(Checklist!I169>0,Checklist!I169, FALSE) -> FALSE | G35: =IF(F35<180, F35-A35, F35-360) -> -360
A36: 45 | C36: =IF(Checklist!I158>0,Checklist!I158, FALSE) -> FALSE | D36: =C36-A36 -> -45 | F36: =IF(Checklist!I170>0,Checklist!I170, FALSE) -> FALSE | G36: =F36-A36 -> -45
A37: 90 | C37: =IF(Checklist!I159>0,Checklist!I159, FALSE) -> FALSE | D37: =C37-A37 -> -90 | F37: =IF(Checklist!I171>0,Checklist!I171, FALSE) -> FALSE | G37: =F37-A37 -> -90
A38: 135 | C38: =IF(Checklist!I160>0,Checklist!I160, FALSE) -> FALSE | D38: =C38-A38 -> -135 | F38: =IF(Checklist!I172>0,Checklist!I172, FALSE) -> FALSE | G38: =F38-A38 -> -135
A39: 180 | C39: =IF(Checklist!I161>0,Checklist!I161, FALSE) -> FALSE | D39: =C39-A39 -> -180 | F39: =IF(Checklist!I173>0,Checklist!I173, FALSE) -> FALSE | G39: =F39-A39 -> -180
A40: 225 | C40: =IF(Checklist!I162>0,Checklist!I162, FALSE) -> FALSE | D40: =C40-A40 -> -225 | F40: =IF(Checklist!I174>0,Checklist!I174, FALSE) -> FALSE | G40: =F40-A40 -> -225
A41: 270 | C41: =IF(Checklist!I163>0,Checklist!I163, FALSE) -> FALSE | D41: =C41-A41 -> -270 | F41: =IF(Checklist!I175>0,Checklist!I175, FALSE) -> FALSE | G41: =F41-A41 -> -270
A42: 315 | C42: =IF(Checklist!I164>0,Checklist!I164, FALSE) -> FALSE | D42: =C42-A42 -> -315 | F42: =IF(Checklist!I176>0,Checklist!I176, FALSE) -> FALSE | G42: =F42-A42 -> -315
A43: 360 | C43: =IF(Checklist!I157>0,Checklist!I157, FALSE) -> FALSE | D43: =D35 -> -360 | F43: =IF(Checklist!I169>0,Checklist!I169, FALSE) -> FALSE | G43: =G35 -> -360
...
